Workbook
Name CurrentRow: [1]Time!$C$14
Name delete: #REF!
Name delete: #REF!
Name delete: #REF!
Name delete: #REF!
Name delete: #REF!
Name delete: #REF!
Name dlete: [1]Time!#REF!
Name dlete: [1]Time!#REF!
Name dlete: [1]Time!#REF!
Name dlete: [1]Time!#REF!
Name dlete: [1]Time!#REF!
Name dlete: [1]Time!#REF!
Name EndRow: [1]Time!#REF!
Name EndRow: [1]Time!#REF!
Name EndRow: [1]Time!#REF!
Name EndRow: [1]Time!#REF!
Name EndRow: [1]Time!#REF!
Name EndRow: [1]Time!#REF!
Name EndRow: [1]Time!#REF!
Name EndRow: [1]Time!#REF!
Name EndRow: [1]Time!#REF!
Name EndRow: [1]Time!#REF!
Name EndRow: [1]Time!#REF!
Name EndRow: [1]Time!#REF!
Name IsExample: TRUE
Name JobNumber: #REF!
Name JobNumber: #REF!
Name JobNumber: #REF!
Name JobNumber: #REF!
Name JobNumber: 'Job Details'!$A$2
Name JobNumber: #REF!
Name JobNumber: #REF!
Name JobNumber: #REF!
Name JobNumber: #REF!
Name JobNumber: #REF!
Name JobNumber: #REF!
Name JobNumber: #REF!
Name JobNumber: #REF!
Name LeClaire: #REF!
Name LeClaire: #REF!
Name LeClaire: #REF!
Name LeClaire: #REF!
Name LeClaire: #REF!
Name LeClaire: #REF!
Name MacroStatus: [1]Information!$E$8
Name PeriodBegin: [1]Time!$C$5
Name PeriodEnd: [1]Time!$C$6
Name qryJCCategory: 'Job Details'!$A$10:$E$229
Name qryJCExtra: 'Job Details'!$G$10:$I$12
Name qryJCExtra: 'Job List'!#REF!
Name qryJCJob1: 'Job List'!$A$2:$H$215
Name qryJCPhase: 'Job Details'!$K$10:$L$40
Name qryPRCertifiedclass: 'Certified Codes'!$A$2:$D$83
Name qryPREmployee: Employees!$A$2:$I$1725
Name SampleValues: '[1]Sample Values'!$C$6:$C$7,'[1]Sample Values'!$C$10:$C$16
Name Skaar: [1]Time!#REF!
Name Skaar: [1]Time!#REF!
Name Skaar: [1]Time!#REF!
Name Skaar: [1]Time!#REF!

Sheet Master Template (9) JOB
AB1: TIME ENTRY SHEET (Template 9) | AZ1: 42917 | BA1: WEEK ENDING: | BB1: 43673
A2: EE: # | C2: <--Enter Employee # to populate all other info
A3: UNION ID | B3: =IF(ISNA(VLOOKUP($B$2,Employees!$B:$H,4,FALSE)),"",VLOOKUP($B$2,Employees!$B:$H,4,FALSE)) | C3: IMPORT TIME? | D3: x | L3: =BB1-5 -> 43668 | R3: =BB1-4 -> 43669 | X3: =BB1-3 -> 43670 | AD3: =BB1-2 -> 43671 | AJ3: =BB1-1 -> 43672 | AP3: =BB1-0 -> 43673 | AV3: =BB1-6 -> 43667
A4: UNION LOCAL | B4: =IF(ISNA(VLOOKUP($B$2,Employees!$B:$H,5,FALSE)),"",VLOOKUP($B$2,Employees!$B:$H,5,FALSE)) | L4: MON | R4: TUE | X4: WED | AD4: THUR | AJ4: FRI | AP4: SAT | AV4: SUN | BB4: TOTALS
K5: Start
K6: Lunch Out
K7: Lunch In
K8: Stop
K9: Total Hours | L9: =IF(AND(L5>=0,L8>=0),(L6-L5+L8-L7)*24,0) -> 0 | R9: =IF(AND(R5>=0,R8>=0),(R6-R5+R8-R7)*24,0) -> 0 | X9: =IF(AND(X5>=0,X8>=0),(X6-X5+X8-X7)*24,0) -> 0 | AD9: =IF(AND(AD5>=0,AD8>=0),(AD6-AD5+AD8-AD7)*24,0) -> 0 | AJ9: =IF(AND(AJ5>=0,AJ8>=0),(AJ6-AJ5+AJ8-AJ7)*24,0) -> 0 | AP9: =IF(AND(AP5>=0,AP8>=0),(AP6-AP5+AP8-AP7)*24,0) -> 0 | AV9: =IF(AND(AV5>=0,AV8>=0),(AV6-AV5+AV8-AV7)*24,0) -> 0 | BB9: =SUM(L9:BA9) -> 0 | BI9: DO NOT TYPE IN OR DELETE FORMULAS
K10: Time Sheet Hours | L10: =L24+M24+N24 -> 0 | R10: =R24+S24+T24 -> 0 | X10: =X24+Y24+Z24 -> 0 | AD10: =AD24+AE24+AF24 -> 0 | AJ10: =AJ24+AK24+AL24 -> 0 | AP10: =AP24+AQ24+AR24 -> 0 | AV10: =AV24+AW24+AX24 -> 0 | BB10: =SUM(L10:BA10) -> 0 | BI10: OC CERTIFIED IMPORT
C11: FILL JOB# IN FIRST | K11: Difference | L11: =L9-L10 -> 0 | R11: =R9-R10 -> 0 | X11: =X9-X10 -> 0 | AD11: =AD9-AD10 -> 0 | AJ11: =AJ9-AJ10 -> 0 | AP11: =AP9-AP10 -> 0 | AV11: =AV9-AV10 -> 0 | BB11: =BB9-BB10 -> 0 | BI11: =L3 -> 43668 | BO11: =R3 -> 43669 | BU11: =X3 -> 43670 | CA11: =AD3 -> 43671 | CG11: =AJ3 -> 43672 | CM11: =AP3 -> 43673 | CS11: =AV3 -> 43667
A12: IMPORT TIME? | B12: WC CODE | C12: JOB | D12: EXTRA | E12: PHASE | F12: UNION LOCAL | G12: WC STATE | H12: ST | I12: UNION CLASS | J12: Cert Class Form | K12: CERT. CLASS | L12: RT1 | M12: OT1 | N12: DT1 | O12: PD1 | P12: 4D1 | Q12: 4A1 | R12: RT2 | S12: OT2 | T12: DT2 | U12: PD2 | V12: 4D2 | W12: 4A2 | X12: RT3 | Y12: OT3 | Z12: DT3 | AA12: PD3 | AB12: 4D3 | AC12: 4A3 | AD12: RT4 | AE12: OT4 | AF12: DT4 | AG12: PD4 | AH12: 4D4 | AI12: 4A4 | AJ12: RT5 | AK12: OT5 | AL12: DT5 | AM12: PD5 | AN12: 4D5 | AO12: 4A5 | AP12: RT6 | AQ12: OT6 | AR12: DT6 | AS12: PD6 | AT12: 4D6 | AU12: 4A6 | AV12: RT7 | AW12: OT7 | AX12: DT7 | AY12: PD7 | AZ12: 4D7 | BA12: 4A7 | BB12: 1 | BC12: 3 | BD12: 2 | BE12: 4 | BF12: 4D | BG12: 4A | BH12: Total | BI12: COC1.1 | BJ12: COC3.1 | BK12: COC2.1 | BL12: COC2.13 | BM12: COC2.12 | BN12: COC4A.1 | BO12: COC1.2 | BP12: COC3.2 | BQ12: COC2.2 | BR12: COC2.23 | BS12: COC2.22 | BT12: COC4A.2 | BU12: COC1.3 | BV12: COC3.3 | BW12: COC2.3 | BX12: COC2.33 | BY12: COC2.32 | BZ12: COC4A.3 | CA12: COC1.4 | CB12: COC3.4 | CC12: COC2.4 | CD12: COC2.43 | CE12: COC2.42 | CF12: COC4A.4 | CG12: COC1.5 | CH12: COC3.5 | CI12: COC2.5 | CJ12: COC2.53 | CK12: COC2.52 | CL12: COC4A.5 | CM12: COC1.6 | CN12: COC3.6 | CO12: COC2.6 | CP12: COC2.63 | CQ12: COC2.62 | CR12: COC4A.6 | CS12: COC1.7 | CT12: COC3.7 | CU12: COC2.7 | CV12: COC2.72 | CW12: COC2.8 | CX12: COC4A.7
A13: =IF(ISBLANK(C13),"",IF(ISBLANK($D$3),"",$D$3)) | F13: =IF(ISBLANK($B$4),"",$B$4) | J13: =IF($K13=0,"",IF($K13<10,"0"&$K13,$K13)) | BB13: =SUM(AV13,AP13,AJ13,AD13,X13,R13,L13) -> 0 | BC13: =SUM(AW13,AQ13,AK13,AE13,Y13,S13,M13) -> 0 | BD13: =SUM(AX13,AR13,AL13,AF13,Z13,T13,N13) -> 0 | BE13: =SUM(AY13,AS13,AM13,AG13,AA13,U13,O13) -> 0 | BF13: =SUM(AZ13,AT13,AN13,AH13,AB13,V13,P13) -> 0 | BG13: =SUM(BA13,AU13,AO13,AI13,AC13,W13,Q13) -> 0 | BH13: =SUM(TimeSheet34[[#This Row],[1]:[4A]]) -> 0 | BI13: =IF(AND(NOT(ISBLANK($C13)),NOT(ISBLANK($E13)),$A13="x"),IF(L13=0,0,[2]!TSImport("PRTime","","Time_NINE","","Date",$BI$11,"Employee",$B$2,"JCJob",$C13,"JCExtra",$D13,"JCCostCode",$E13,"WCCode",$B13,"WCState",$G13,"State",$H13,"PayID",$BB$12,"Units",L13,"UnionID",$B$3,"UnionLocal",$F13,"UnionClass",$I13,"CertifiedClass",$J13)),0) -> 0 | BJ13: =IF(AND(NOT(ISBLANK($C13)),NOT(ISBLANK($E13)),$A13="x"),IF(M13=0,0,[2]!TSImport("PRTime","","Time_NINE","","Date",$BI$11,"Employee",$B$2,"JCJob",$C13,"JCExtra",$D13,"JCCostCode",$E13,"WCCode",$B13,"WCState",$G13,"State",$H13,"PayID",$BC$12,"Units",M13,"UnionID",$B$3,"UnionLocal",$F13,"UnionClass",$I13,"CertifiedClass",$J13)),0) -> 0 | BK13: =IF(AND(NOT(ISBLANK($C13)),NOT(ISBLANK($E13)),$A13="x"),IF(N13=0,0,[2]!TSImport("PRTime","","Time_NINE","","Date",$BI$11,"Employee",$B$2,"JCJob",$C13,"JCExtra",$D13,"JCCostCode",$E13,"WCCode",$B13,"WCState",$G13,"State",$H13,"PayID",$BD$12,"Units",N13,"UnionID",$B$3,"UnionLocal",$F13,"UnionClass",$I13,"CertifiedClass",$J13)),0) -> 0 | BL13: =IF(AND(NOT(ISBLANK($C13)),NOT(ISBLANK($E13)),$A13="x"),IF(O13=0,0,[2]!TSImport("PRTime","","Time_NINE","","Date",$BI$11,"Employee",$B$2,"JCJob",$C13,"JCExtra",$D13,"JCCostCode",$E13,"WCCode",$B13,"WCState",$G13,"State",$H13,"PayID",$BE$12,"Units",O13,"UnionID",$B$3,"UnionLocal",$F13,"UnionClass",$I13,"CertifiedClass",$J13)),0) -> 0 | BM13: =IF(AND(NOT(ISBLANK($C13)),NOT(ISBLANK($E13)),$A13="x"),IF(P13=0,0,[2]!TSImport("PRTime","","Time_NINE","","Date",$BI$11,"Employee",$B$2,"JCJob",$C13,"JCExtra",$D13,"JCCostCode",$E13,"WCCode",$B13,"WCState",$G13,"State",$H13,"PayID",$BF$12,"Units",P13,"UnionID",$B$3,"UnionLocal",$F13,"UnionClass",$I13,"CertifiedClass",$J13)),0) -> 0 | BN13: =IF(AND(NOT(ISBLANK($C13)),NOT(ISBLANK($E13)),$A13="x"),IF(Q13=0,0,[2]!TSImport("PRTime","","Time_NINE","","Date",$BI$11,"Employee",$B$2,"JCJob",$C13,"JCExtra",$D13,"JCCostCode",$E13,"WCCode",$B13,"WCState",$G13,"State",$H13,"PayID",$BG$12,"Units",Q13,"UnionID",$B$3,"UnionLocal",$F13,"UnionClass",$I13,"CertifiedClass",$J13)),0) -> 0 | BO13: =IF(AND(NOT(ISBLANK($C13)),NOT(ISBLANK($E13)),$A13="x"),IF(R13=0,0,[2]!TSImport("PRTime","","Time_NINE","","Date",$BO$11,"Employee",$B$2,"JCJob",$C13,"JCExtra",$D13,"JCCostCode",$E13,"WCCode",$B13,"WCState",$G13,"State",$H13,"PayID",$BB$12,"Units",R13,"UnionID",$B$3,"UnionLocal",$F13,"UnionClass",$I13,"CertifiedClass",$J13)),0) -> 0 | BP13: =IF(AND(NOT(ISBLANK($C13)),NOT(ISBLANK($E13)),$A13="x"),IF(S13=0,0,[2]!TSImport("PRTime","","Time_NINE","","Date",$BO$11,"Employee",$B$2,"JCJob",$C13,"JCExtra",$D13,"JCCostCode",$E13,"WCCode",$B13,"WCState",$G13,"State",$H13,"PayID",$BC$12,"Units",S13,"UnionID",$B$3,"UnionLocal",$F13,"UnionClass",$I13,"CertifiedClass",$J13)),0) -> 0 | BQ13: =IF(AND(NOT(ISBLANK($C13)),NOT(ISBLANK($E13)),$A13="x"),IF(T13=0,0,[2]!TSImport("PRTime","","Time_NINE","","Date",$BO$11,"Employee",$B$2,"JCJob",$C13,"JCExtra",$D13,"JCCostCode",$E13,"WCCode",$B13,"WCState",$G13,"State",$H13,"PayID",$BD$12,"Units",T13,"UnionID",$B$3,"UnionLocal",$F13,"UnionClass",$I13,"CertifiedClass",$J13)),0) -> 0 | BR13: =IF(AND(NOT(ISBLANK($C13)),NOT(ISBLANK($E13)),$A13="x"),IF(U13=0,0,[2]!TSImport("PRTime","","Time_NINE","","Date",$BO$11,"Employee",$B$2,"JCJob",$C13,"JCExtra",$D13,"JCCostCode",$E13,"WCCode",$B13,"WCState",$G13,"State",$H13,"PayID",$BE$12,"Units",U13,"UnionID",$B$3,"UnionLocal",$F13,"UnionClass",$I13,"CertifiedClass",$J13)),0) -> 0 | BS13: =IF(AND(NOT(ISBLANK($C13)),NOT(ISBLANK($E13)),$A13="x"),IF(V13=0,0,[2]!TSImport("PRTime","","Time_NINE","","Date",$BO$11,"Employee",$B$2,"JCJob",$C13,"JCExtra",$D13,"JCCostCode",$E13,"WCCode",$B13,"WCState",$G13,"State",$H13,"PayID",$BF$12,"Units",V13,"UnionID",$B$3,"UnionLocal",$F13,"UnionClass",$I13,"CertifiedClass",$J13)),0) -> 0 | BT13: =IF(AND(NOT(ISBLANK($C13)),NOT(ISBLANK($E13)),$A13="x"),IF(W13=0,0,[2]!TSImport("PRTime","","Time_NINE","","Date",$BO$11,"Employee",$B$2,"JCJob",$C13,"JCExtra",$D13,"JCCostCode",$E13,"WCCode",$B13,"WCState",$G13,"State",$H13,"PayID",$BG$12,"Units",W13,"UnionID",$B$3,"UnionLocal",$F13,"UnionClass",$I13,"CertifiedClass",$J13)),0) -> 0 | BU13: =IF(AND(NOT(ISBLANK($C13)),NOT(ISBLANK($E13)),$A13="x"),IF(X13=0,0,[2]!TSImport("PRTime","","Time_NINE","","Date",$BU$11,"Employee",$B$2,"JCJob",$C13,"JCExtra",$D13,"JCCostCode",$E13,"WCCode",$B13,"WCState",$G13,"State",$H13,"PayID",$BB$12,"Units",X13,"UnionID",$B$3,"UnionLocal",$F13,"UnionClass",$I13,"CertifiedClass",$J13)),0) -> 0 | BV13: =IF(AND(NOT(ISBLANK($C13)),NOT(ISBLANK($E13)),$A13="x"),IF(Y13=0,0,[2]!TSImport("PRTime","","Time_NINE","","Date",$BU$11,"Employee",$B$2,"JCJob",$C13,"JCExtra",$D13,"JCCostCode",$E13,"WCCode",$B13,"WCState",$G13,"State",$H13,"PayID",$BC$12,"Units",Y13,"UnionID",$B$3,"UnionLocal",$F13,"UnionClass",$I13,"CertifiedClass",$J13)),0) -> 0 | BW13: =IF(AND(NOT(ISBLANK($C13)),NOT(ISBLANK($E13)),$A13="x"),IF(Z13=0,0,[2]!TSImport("PRTime","","Time_NINE","","Date",$BU$11,"Employee",$B$2,"JCJob",$C13,"JCExtra",$D13,"JCCostCode",$E13,"WCCode",$B13,"WCState",$G13,"State",$H13,"PayID",$BD$12,"Units",Z13,"UnionID",$B$3,"UnionLocal",$F13,"UnionClass",$I13,"CertifiedClass",$J13)),0) -> 0 | BX13: =IF(AND(NOT(ISBLANK($C13)),NOT(ISBLANK($E13)),$A13="x"),IF(AA13=0,0,[2]!TSImport("PRTime","","Time_NINE","","Date",$BU$11,"Employee",$B$2,"JCJob",$C13,"JCExtra",$D13,"JCCostCode",$E13,"WCCode",$B13,"WCState",$G13,"State",$H13,"PayID",$BE$12,"Units",AA13,"UnionID",$B$3,"UnionLocal",$F13,"UnionClass",$I13,"CertifiedClass",$J13)),0) -> 0 | BY13: =IF(AND(NOT(ISBLANK($C13)),NOT(ISBLANK($E13)),$A13="x"),IF(AB13=0,0,[2]!TSImport("PRTime","","Time_NINE","","Date",$BU$11,"Employee",$B$2,"JCJob",$C13,"JCExtra",$D13,"JCCostCode",$E13,"WCCode",$B13,"WCState",$G13,"State",$H13,"PayID",$BF$12,"Units",AB13,"UnionID",$B$3,"UnionLocal",$F13,"UnionClass",$I13,"CertifiedClass",$J13)),0) -> 0 | BZ13: =IF(AND(NOT(ISBLANK($C13)),NOT(ISBLANK($E13)),$A13="x"),IF(AC13=0,0,[2]!TSImport("PRTime","","Time_NINE","","Date",$BU$11,"Employee",$B$2,"JCJob",$C13,"JCExtra",$D13,"JCCostCode",$E13,"WCCode",$B13,"WCState",$G13,"State",$H13,"PayID",$BG$12,"Units",AC13,"UnionID",$B$3,"UnionLocal",$F13,"UnionClass",$I13,"CertifiedClass",$J13)),0) -> 0 | CA13: =IF(AND(NOT(ISBLANK($C13)),NOT(ISBLANK($E13)),$A13="x"),IF(AD13=0,0,[2]!TSImport("PRTime","","Time_NINE","","Date",$CA$11,"Employee",$B$2,"JCJob",$C13,"JCExtra",$D13,"JCCostCode",$E13,"WCCode",$B13,"WCState",$G13,"State",$H13,"PayID",$BB$12,"Units",AD13,"UnionID",$B$3,"UnionLocal",$F13,"UnionClass",$I13,"CertifiedClass",$J13)),0) -> 0 | CB13: =IF(AND(NOT(ISBLANK($C13)),NOT(ISBLANK($E13)),$A13="x"),IF(AE13=0,0,[2]!TSImport("PRTime","","Time_NINE","","Date",$CA$11,"Employee",$B$2,"JCJob",$C13,"JCExtra",$D13,"JCCostCode",$E13,"WCCode",$B13,"WCState",$G13,"State",$H13,"PayID",$BC$12,"Units",AE13,"UnionID",$B$3,"UnionLocal",$F13,"UnionClass",$I13,"CertifiedClass",$J13)),0) -> 0 | CC13: =IF(AND(NOT(ISBLANK($C13)),NOT(ISBLANK($E13)),$A13="x"),IF(AF13=0,0,[2]!TSImport("PRTime","","Time_NINE","","Date",$CA$11,"Employee",$B$2,"JCJob",$C13,"JCExtra",$D13,"JCCostCode",$E13,"WCCode",$B13,"WCState",$G13,"State",$H13,"PayID",$BD$12,"Units",AF13,"UnionID",$B$3,"UnionLocal",$F13,"UnionClass",$I13,"CertifiedClass",$J13)),0) -> 0 | CD13: =IF(AND(NOT(ISBLANK($C13)),NOT(ISBLANK($E13)),$A13="x"),IF(AG13=0,0,[2]!TSImport("PRTime","","Time_NINE","","Date",$CA$11,"Employee",$B$2,"JCJob",$C13,"JCExtra",$D13,"JCCostCode",$E13,"WCCode",$B13,"WCState",$G13,"State",$H13,"PayID",$BE$12,"Units",AG13,"UnionID",$B$3,"UnionLocal",$F13,"UnionClass",$I13,"CertifiedClass",$J13)),0) -> 0 | CE13: =IF(AND(NOT(ISBLANK($C13)),NOT(ISBLANK($E13)),$A13="x"),IF(AH13=0,0,[2]!TSImport("PRTime","","Time_NINE","","Date",$CA$11,"Employee",$B$2,"JCJob",$C13,"JCExtra",$D13,"JCCostCode",$E13,"WCCode",$B13,"WCState",$G13,"State",$H13,"PayID",$BF$12,"Units",AH13,"UnionID",$B$3,"UnionLocal",$F13,"UnionClass",$I13,"CertifiedClass",$J13)),0) -> 0 | CF13: =IF(AND(NOT(ISBLANK($C13)),NOT(ISBLANK($E13)),$A13="x"),IF(AI13=0,0,[2]!TSImport("PRTime","","Time_NINE","","Date",$CA$11,"Employee",$B$2,"JCJob",$C13,"JCExtra",$D13,"JCCostCode",$E13,"WCCode",$B13,"WCState",$G13,"State",$H13,"PayID",$BG$12,"Units",AI13,"UnionID",$B$3,"UnionLocal",$F13,"UnionClass",$I13,"CertifiedClass",$J13)),0) -> 0 | CG13: =IF(AND(NOT(ISBLANK($C13)),NOT(ISBLANK($E13)),$A13="x"),IF(AJ13=0,0,[2]!TSImport("PRTime","","Time_NINE","","Date",$CG$11,"Employee",$B$2,"JCJob",$C13,"JCExtra",$D13,"JCCostCode",$E13,"WCCode",$B13,"WCState",$G13,"State",$H13,"PayID",$BB$12,"Units",AJ13,"UnionID",$B$3,"UnionLocal",$F13,"UnionClass",$I13,"CertifiedClass",$J13)),0) -> 0 | CH13: =IF(AND(NOT(ISBLANK($C13)),NOT(ISBLANK($E13)),$A13="x"),IF(AK13=0,0,[2]!TSImport("PRTime","","Time_NINE","","Date",$CG$11,"Employee",$B$2,"JCJob",$C13,"JCExtra",$D13,"JCCostCode",$E13,"WCCode",$B13,"WCState",$G13,"State",$H13,"PayID",$BC$12,"Units",AK13,"UnionID",$B$3,"UnionLocal",$F13,"UnionClass",$I13,"CertifiedClass",$J13)),0) -> 0 | CI13: =IF(AND(NOT(ISBLANK($C13)),NOT(ISBLANK($E13)),$A13="x"),IF(AL13=0,0,[2]!TSImport("PRTime","","Time_NINE","","Date",$CG$11,"Employee",$B$2,"JCJob",$C13,"JCExtra",$D13,"JCCostCode",$E13,"WCCode",$B13,"WCState",$G13,"State",$H13,"PayID",$BD$12,"Units",AL13,"UnionID",$B$3,"UnionLocal",$F13,"UnionClass",$I13,"CertifiedClass",$J13)),0) -> 0 | CJ13: =IF(AND(NOT(ISBLANK($C13)),NOT(ISBLANK($E13)),$A13="x"),IF(AM13=0,0,[2]!TSImport("PRTime","","Time_NINE","","Date",$CG$11,"Employee",$B$2,"JCJob",$C13,"JCExtra",$D13,"JCCostCode",$E13,"WCCode",$B13,"WCState",$G13,"State",$H13,"PayID",$BE$12,"Units",AM13,"UnionID",$B$3,"UnionLocal",$F13,"UnionClass",$I13,"CertifiedClass",$J13)),0) -> 0 | CK13: =IF(AND(NOT(ISBLANK($C13)),NOT(ISBLANK($E13)),$A13="x"),IF(AN13=0,0,[2]!TSImport("PRTime","","Time_NINE","","Date",$CG$11,"Employee",$B$2,"JCJob",$C13,"JCExtra",$D13,"JCCostCode",$E13,"WCCode",$B13,"WCState",$G13,"State",$H13,"PayID",$BF$12,"Units",AN13,"UnionID",$B$3,"UnionLocal",$F13,"UnionClass",$I13,"CertifiedClass",$J13)),0) -> 0 | CL13: =IF(AND(NOT(ISBLANK($C13)),NOT(ISBLANK($E13)),$A13="x"),IF(AO13=0,0,[2]!TSImport("PRTime","","Time_NINE","","Date",$CG$11,"Employee",$B$2,"JCJob",$C13,"JCExtra",$D13,"JCCostCode",$E13,"WCCode",$B13,"WCState",$G13,"State",$H13,"PayID",$BG$12,"Units",AO13,"UnionID",$B$3,"UnionLocal",$F13,"UnionClass",$I13,"CertifiedClass",$J13)),0) -> 0 | CM13: =IF(AND(NOT(ISBLANK($C13)),NOT(ISBLANK($E13)),$A13="x"),IF(AP13=0,0,[2]!TSImport("PRTime","","Time_NINE","","Date",$CM$11,"Employee",$B$2,"JCJob",$C13,"JCExtra",$D13,"JCCostCode",$E13,"WCCode",$B13,"WCState",$G13,"State",$H13,"PayID",$BB$12,"Units",AP13,"UnionID",$B$3,"UnionLocal",$F13,"UnionClass",$I13,"CertifiedClass",$J13)),0) -> 0 | CN13: =IF(AND(NOT(ISBLANK($C13)),NOT(ISBLANK($E13)),$A13="x"),IF(AQ13=0,0,[2]!TSImport("PRTime","","Time_NINE","","Date",$CM$11,"Employee",$B$2,"JCJob",$C13,"JCExtra",$D13,"JCCostCode",$E13,"WCCode",$B13,"WCState",$G13,"State",$H13,"PayID",$BC$12,"Units",AQ13,"UnionID",$B$3,"UnionLocal",$F13,"UnionClass",$I13,"CertifiedClass",$J13)),0) -> 0 | CO13: =IF(AND(NOT(ISBLANK($C13)),NOT(ISBLANK($E13)),$A13="x"),IF(AR13=0,0,[2]!TSImport("PRTime","","Time_NINE","","Date",$CM$11,"Employee",$B$2,"JCJob",$C13,"JCExtra",$D13,"JCCostCode",$E13,"WCCode",$B13,"WCState",$G13,"State",$H13,"PayID",$BD$12,"Units",AR13,"UnionID",$B$3,"UnionLocal",$F13,"UnionClass",$I13,"CertifiedClass",$J13)),0) -> 0 | CP13: =IF(AND(NOT(ISBLANK($C13)),NOT(ISBLANK($E13)),$A13="x"),IF(AS13=0,0,[2]!TSImport("PRTime","","Time_NINE","","Date",$CM$11,"Employee",$B$2,"JCJob",$C13,"JCExtra",$D13,"JCCostCode",$E13,"WCCode",$B13,"WCState",$G13,"State",$H13,"PayID",$BE$12,"Units",AS13,"UnionID",$B$3,"UnionLocal",$F13,"UnionClass",$I13,"CertifiedClass",$J13)),0) -> 0 | CQ13: =IF(AND(NOT(ISBLANK($C13)),NOT(ISBLANK($E13)),$A13="x"),IF(AT13=0,0,[2]!TSImport("PRTime","","Time_NINE","","Date",$CM$11,"Employee",$B$2,"JCJob",$C13,"JCExtra",$D13,"JCCostCode",$E13,"WCCode",$B13,"WCState",$G13,"State",$H13,"PayID",$BF$12,"Units",AT13,"UnionID",$B$3,"UnionLocal",$F13,"UnionClass",$I13,"CertifiedClass",$J13)),0) -> 0 | CR13: =IF(AND(NOT(ISBLANK($C13)),NOT(ISBLANK($E13)),$A13="x"),IF(AU13=0,0,[2]!TSImport("PRTime","","Time_NINE","","Date",$CM$11,"Employee",$B$2,"JCJob",$C13,"JCExtra",$D13,"JCCostCode",$E13,"WCCode",$B13,"WCState",$G13,"State",$H13,"PayID",$BG$12,"Units",AU13,"UnionID",$B$3,"UnionLocal",$F13,"UnionClass",$I13,"CertifiedClass",$J13)),0) -> 0 | CS13: =IF(AND(NOT(ISBLANK($C13)),NOT(ISBLANK($E13)),$A13="x"),IF(AV13=0,0,[2]!TSImport("PRTime","","Time_NINE","","Date",$CS$11,"Employee",$B$2,"JCJob",$C13,"JCExtra",$D13,"JCCostCode",$E13,"WCCode",$B13,"WCState",$G13,"State",$H13,"PayID",$BB$12,"Units",AV13,"UnionID",$B$3,"UnionLocal",$F13,"UnionClass",$I13,"CertifiedClass",$J13)),0) -> 0 | CT13: =IF(AND(NOT(ISBLANK($C13)),NOT(ISBLANK($E13)),$A13="x"),IF(AW13=0,0,[2]!TSImport("PRTime","","Time_NINE","","Date",$CS$11,"Employee",$B$2,"JCJob",$C13,"JCExtra",$D13,"JCCostCode",$E13,"WCCode",$B13,"WCState",$G13,"State",$H13,"PayID",$BC$12,"Units",AW13,"UnionID",$B$3,"UnionLocal",$F13,"UnionClass",$I13,"CertifiedClass",$J13)),0) -> 0 | CU13: =IF(AND(NOT(ISBLANK($C13)),NOT(ISBLANK($E13)),$A13="x"),IF(AX13=0,0,[2]!TSImport("PRTime","","Time_NINE","","Date",$CS$11,"Employee",$B$2,"JCJob",$C13,"JCExtra",$D13,"JCCostCode",$E13,"WCCode",$B13,"WCState",$G13,"State",$H13,"PayID",$BD$12,"Units",AX13,"UnionID",$B$3,"UnionLocal",$F13,"UnionClass",$I13,"CertifiedClass",$J13)),0) -> 0 | CV13: =IF(AND(NOT(ISBLANK($C13)),NOT(ISBLANK($E13)),$A13="x"),IF(AY13=0,0,[2]!TSImport("PRTime","","Time_NINE","","Date",$CS$11,"Employee",$B$2,"JCJob",$C13,"JCExtra",$D13,"JCCostCode",$E13,"WCCode",$B13,"WCState",$G13,"State",$H13,"PayID",$BE$12,"Units",AY13,"UnionID",$B$3,"UnionLocal",$F13,"UnionClass",$I13,"CertifiedClass",$J13)),0) -> 0 | CW13: =IF(AND(NOT(ISBLANK($C13)),NOT(ISBLANK($E13)),$A13="x"),IF(AZ13=0,0,[2]!TSImport("PRTime","","Time_NINE","","Date",$CS$11,"Employee",$B$2,"JCJob",$C13,"JCExtra",$D13,"JCCostCode",$E13,"WCCode",$B13,"WCState",$G13,"State",$H13,"PayID",$BF$12,"Units",AZ13,"UnionID",$B$3,"UnionLocal",$F13,"UnionClass",$I13,"CertifiedClass",$J13)),0) -> 0 | CX13: =IF(AND(NOT(ISBLANK($C13)),NOT(ISBLANK($E13)),$A13="x"),IF(BA13=0,0,[2]!TSImport("PRTime","","Time_NINE","","Date",$CS$11,"Employee",$B$2,"JCJob",$C13,"JCExtra",$D13,"JCCostCode",$E13,"WCCode",$B13,"WCState",$G13,"State",$H13,"PayID",$BG$12,"Units",BA13,"UnionID",$B$3,"UnionLocal",$F13,"UnionClass",$I13,"CertifiedClass",$J13)),0) -> 0
A14: =IF(ISBLANK(C14),"",IF(ISBLANK($D$3),"",$D$3)) | F14: =IF(ISBLANK($B$4),"",$B$4) | J14: =IF($K14=0,"",IF($K14<10,"0"&$K14,$K14)) | BB14: =SUM(AV14,AP14,AJ14,AD14,X14,R14,L14) -> 0 | BC14: =SUM(AW14,AQ14,AK14,AE14,Y14,S14,M14) -> 0 | BD14: =SUM(AX14,AR14,AL14,AF14,Z14,T14,N14) -> 0 | BE14: =SUM(AY14,AS14,AM14,AG14,AA14,U14,O14) -> 0 | BF14: =SUM(AZ14,AT14,AN14,AH14,AB14,V14,P14) -> 0 | BG14: =SUM(BA14,AU14,AO14,AI14,AC14,W14,Q14) -> 0 | BH14: =SUM(TimeSheet34[[#This Row],[1]:[4A]]) -> 0 | BI14: =IF(AND(NOT(ISBLANK($C14)),NOT(ISBLANK($E14)),$A14="x"),IF(L14=0,0,[2]!TSImport("PRTime","","Time_NINE","","Date",$BI$11,"Employee",$B$2,"JCJob",$C14,"JCExtra",$D14,"JCCostCode",$E14,"WCCode",$B14,"WCState",$G14,"State",$H14,"PayID",$BB$12,"Units",L14,"UnionID",$B$3,"UnionLocal",$F14,"UnionClass",$I14,"CertifiedClass",$J14)),0) -> 0 | BJ14: =IF(AND(NOT(ISBLANK($C14)),NOT(ISBLANK($E14)),$A14="x"),IF(M14=0,0,[2]!TSImport("PRTime","","Time_NINE","","Date",$BI$11,"Employee",$B$2,"JCJob",$C14,"JCExtra",$D14,"JCCostCode",$E14,"WCCode",$B14,"WCState",$G14,"State",$H14,"PayID",$BC$12,"Units",M14,"UnionID",$B$3,"UnionLocal",$F14,"UnionClass",$I14,"CertifiedClass",$J14)),0) -> 0 | BK14: =IF(AND(NOT(ISBLANK($C14)),NOT(ISBLANK($E14)),$A14="x"),IF(N14=0,0,[2]!TSImport("PRTime","","Time_NINE","","Date",$BI$11,"Employee",$B$2,"JCJob",$C14,"JCExtra",$D14,"JCCostCode",$E14,"WCCode",$B14,"WCState",$G14,"State",$H14,"PayID",$BD$12,"Units",N14,"UnionID",$B$3,"UnionLocal",$F14,"UnionClass",$I14,"CertifiedClass",$J14)),0) -> 0 | BL14: =IF(AND(NOT(ISBLANK($C14)),NOT(ISBLANK($E14)),$A14="x"),IF(O14=0,0,[2]!TSImport("PRTime","","Time_NINE","","Date",$BI$11,"Employee",$B$2,"JCJob",$C14,"JCExtra",$D14,"JCCostCode",$E14,"WCCode",$B14,"WCState",$G14,"State",$H14,"PayID",$BE$12,"Units",O14,"UnionID",$B$3,"UnionLocal",$F14,"UnionClass",$I14,"CertifiedClass",$J14)),0) -> 0 | BM14: =IF(AND(NOT(ISBLANK($C14)),NOT(ISBLANK($E14)),$A14="x"),IF(P14=0,0,[2]!TSImport("PRTime","","Time_NINE","","Date",$BI$11,"Employee",$B$2,"JCJob",$C14,"JCExtra",$D14,"JCCostCode",$E14,"WCCode",$B14,"WCState",$G14,"State",$H14,"PayID",$BF$12,"Units",P14,"UnionID",$B$3,"UnionLocal",$F14,"UnionClass",$I14,"CertifiedClass",$J14)),0) -> 0 | BN14: =IF(AND(NOT(ISBLANK($C14)),NOT(ISBLANK($E14)),$A14="x"),IF(Q14=0,0,[2]!TSImport("PRTime","","Time_NINE","","Date",$BI$11,"Employee",$B$2,"JCJob",$C14,"JCExtra",$D14,"JCCostCode",$E14,"WCCode",$B14,"WCState",$G14,"State",$H14,"PayID",$BG$12,"Units",Q14,"UnionID",$B$3,"UnionLocal",$F14,"UnionClass",$I14,"CertifiedClass",$J14)),0) -> 0 | BO14: =IF(AND(NOT(ISBLANK($C14)),NOT(ISBLANK($E14)),$A14="x"),IF(R14=0,0,[2]!TSImport("PRTime","","Time_NINE","","Date",$BO$11,"Employee",$B$2,"JCJob",$C14,"JCExtra",$D14,"JCCostCode",$E14,"WCCode",$B14,"WCState",$G14,"State",$H14,"PayID",$BB$12,"Units",R14,"UnionID",$B$3,"UnionLocal",$F14,"UnionClass",$I14,"CertifiedClass",$J14)),0) -> 0 | BP14: =IF(AND(NOT(ISBLANK($C14)),NOT(ISBLANK($E14)),$A14="x"),IF(S14=0,0,[2]!TSImport("PRTime","","Time_NINE","","Date",$BO$11,"Employee",$B$2,"JCJob",$C14,"JCExtra",$D14,"JCCostCode",$E14,"WCCode",$B14,"WCState",$G14,"State",$H14,"PayID",$BC$12,"Units",S14,"UnionID",$B$3,"UnionLocal",$F14,"UnionClass",$I14,"CertifiedClass",$J14)),0) -> 0 | BQ14: =IF(AND(NOT(ISBLANK($C14)),NOT(ISBLANK($E14)),$A14="x"),IF(T14=0,0,[2]!TSImport("PRTime","","Time_NINE","","Date",$BO$11,"Employee",$B$2,"JCJob",$C14,"JCExtra",$D14,"JCCostCode",$E14,"WCCode",$B14,"WCState",$G14,"State",$H14,"PayID",$BD$12,"Units",T14,"UnionID",$B$3,"UnionLocal",$F14,"UnionClass",$I14,"CertifiedClass",$J14)),0) -> 0 | BR14: =IF(AND(NOT(ISBLANK($C14)),NOT(ISBLANK($E14)),$A14="x"),IF(U14=0,0,[2]!TSImport("PRTime","","Time_NINE","","Date",$BO$11,"Employee",$B$2,"JCJob",$C14,"JCExtra",$D14,"JCCostCode",$E14,"WCCode",$B14,"WCState",$G14,"State",$H14,"PayID",$BE$12,"Units",U14,"UnionID",$B$3,"UnionLocal",$F14,"UnionClass",$I14,"CertifiedClass",$J14)),0) -> 0 | BS14: =IF(AND(NOT(ISBLANK($C14)),NOT(ISBLANK($E14)),$A14="x"),IF(V14=0,0,[2]!TSImport("PRTime","","Time_NINE","","Date",$BO$11,"Employee",$B$2,"JCJob",$C14,"JCExtra",$D14,"JCCostCode",$E14,"WCCode",$B14,"WCState",$G14,"State",$H14,"PayID",$BF$12,"Units",V14,"UnionID",$B$3,"UnionLocal",$F14,"UnionClass",$I14,"CertifiedClass",$J14)),0) -> 0 | BT14: =IF(AND(NOT(ISBLANK($C14)),NOT(ISBLANK($E14)),$A14="x"),IF(W14=0,0,[2]!TSImport("PRTime","","Time_NINE","","Date",$BO$11,"Employee",$B$2,"JCJob",$C14,"JCExtra",$D14,"JCCostCode",$E14,"WCCode",$B14,"WCState",$G14,"State",$H14,"PayID",$BG$12,"Units",W14,"UnionID",$B$3,"UnionLocal",$F14,"UnionClass",$I14,"CertifiedClass",$J14)),0) -> 0 | BU14: =IF(AND(NOT(ISBLANK($C14)),NOT(ISBLANK($E14)),$A14="x"),IF(X14=0,0,[2]!TSImport("PRTime","","Time_NINE","","Date",$BU$11,"Employee",$B$2,"JCJob",$C14,"JCExtra",$D14,"JCCostCode",$E14,"WCCode",$B14,"WCState",$G14,"State",$H14,"PayID",$BB$12,"Units",X14,"UnionID",$B$3,"UnionLocal",$F14,"UnionClass",$I14,"CertifiedClass",$J14)),0) -> 0 | BV14: =IF(AND(NOT(ISBLANK($C14)),NOT(ISBLANK($E14)),$A14="x"),IF(Y14=0,0,[2]!TSImport("PRTime","","Time_NINE","","Date",$BU$11,"Employee",$B$2,"JCJob",$C14,"JCExtra",$D14,"JCCostCode",$E14,"WCCode",$B14,"WCState",$G14,"State",$H14,"PayID",$BC$12,"Units",Y14,"UnionID",$B$3,"UnionLocal",$F14,"UnionClass",$I14,"CertifiedClass",$J14)),0) -> 0 | BW14: =IF(AND(NOT(ISBLANK($C14)),NOT(ISBLANK($E14)),$A14="x"),IF(Z14=0,0,[2]!TSImport("PRTime","","Time_NINE","","Date",$BU$11,"Employee",$B$2,"JCJob",$C14,"JCExtra",$D14,"JCCostCode",$E14,"WCCode",$B14,"WCState",$G14,"State",$H14,"PayID",$BD$12,"Units",Z14,"UnionID",$B$3,"UnionLocal",$F14,"UnionClass",$I14,"CertifiedClass",$J14)),0) -> 0 | BX14: =IF(AND(NOT(ISBLANK($C14)),NOT(ISBLANK($E14)),$A14="x"),IF(AA14=0,0,[2]!TSImport("PRTime","","Time_NINE","","Date",$BU$11,"Employee",$B$2,"JCJob",$C14,"JCExtra",$D14,"JCCostCode",$E14,"WCCode",$B14,"WCState",$G14,"State",$H14,"PayID",$BE$12,"Units",AA14,"UnionID",$B$3,"UnionLocal",$F14,"UnionClass",$I14,"CertifiedClass",$J14)),0) -> 0 | BY14: =IF(AND(NOT(ISBLANK($C14)),NOT(ISBLANK($E14)),$A14="x"),IF(AB14=0,0,[2]!TSImport("PRTime","","Time_NINE","","Date",$BU$11,"Employee",$B$2,"JCJob",$C14,"JCExtra",$D14,"JCCostCode",$E14,"WCCode",$B14,"WCState",$G14,"State",$H14,"PayID",$BF$12,"Units",AB14,"UnionID",$B$3,"UnionLocal",$F14,"UnionClass",$I14,"CertifiedClass",$J14)),0) -> 0 | BZ14: =IF(AND(NOT(ISBLANK($C14)),NOT(ISBLANK($E14)),$A14="x"),IF(AC14=0,0,[2]!TSImport("PRTime","","Time_NINE","","Date",$BU$11,"Employee",$B$2,"JCJob",$C14,"JCExtra",$D14,"JCCostCode",$E14,"WCCode",$B14,"WCState",$G14,"State",$H14,"PayID",$BG$12,"Units",AC14,"UnionID",$B$3,"UnionLocal",$F14,"UnionClass",$I14,"CertifiedClass",$J14)),0) -> 0 | CA14: =IF(AND(NOT(ISBLANK($C14)),NOT(ISBLANK($E14)),$A14="x"),IF(AD14=0,0,[2]!TSImport("PRTime","","Time_NINE","","Date",$CA$11,"Employee",$B$2,"JCJob",$C14,"JCExtra",$D14,"JCCostCode",$E14,"WCCode",$B14,"WCState",$G14,"State",$H14,"PayID",$BB$12,"Units",AD14,"UnionID",$B$3,"UnionLocal",$F14,"UnionClass",$I14,"CertifiedClass",$J14)),0) -> 0 | CB14: =IF(AND(NOT(ISBLANK($C14)),NOT(ISBLANK($E14)),$A14="x"),IF(AE14=0,0,[2]!TSImport("PRTime","","Time_NINE","","Date",$CA$11,"Employee",$B$2,"JCJob",$C14,"JCExtra",$D14,"JCCostCode",$E14,"WCCode",$B14,"WCState",$G14,"State",$H14,"PayID",$BC$12,"Units",AE14,"UnionID",$B$3,"UnionLocal",$F14,"UnionClass",$I14,"CertifiedClass",$J14)),0) -> 0 | CC14: =IF(AND(NOT(ISBLANK($C14)),NOT(ISBLANK($E14)),$A14="x"),IF(AF14=0,0,[2]!TSImport("PRTime","","Time_NINE","","Date",$CA$11,"Employee",$B$2,"JCJob",$C14,"JCExtra",$D14,"JCCostCode",$E14,"WCCode",$B14,"WCState",$G14,"State",$H14,"PayID",$BD$12,"Units",AF14,"UnionID",$B$3,"UnionLocal",$F14,"UnionClass",$I14,"CertifiedClass",$J14)),0) -> 0 | CD14: =IF(AND(NOT(ISBLANK($C14)),NOT(ISBLANK($E14)),$A14="x"),IF(AG14=0,0,[2]!TSImport("PRTime","","Time_NINE","","Date",$CA$11,"Employee",$B$2,"JCJob",$C14,"JCExtra",$D14,"JCCostCode",$E14,"WCCode",$B14,"WCState",$G14,"State",$H14,"PayID",$BE$12,"Units",AG14,"UnionID",$B$3,"UnionLocal",$F14,"UnionClass",$I14,"CertifiedClass",$J14)),0) -> 0 | CE14: =IF(AND(NOT(ISBLANK($C14)),NOT(ISBLANK($E14)),$A14="x"),IF(AH14=0,0,[2]!TSImport("PRTime","","Time_NINE","","Date",$CA$11,"Employee",$B$2,"JCJob",$C14,"JCExtra",$D14,"JCCostCode",$E14,"WCCode",$B14,"WCState",$G14,"State",$H14,"PayID",$BF$12,"Units",AH14,"UnionID",$B$3,"UnionLocal",$F14,"UnionClass",$I14,"CertifiedClass",$J14)),0) -> 0 | CF14: =IF(AND(NOT(ISBLANK($C14)),NOT(ISBLANK($E14)),$A14="x"),IF(AI14=0,0,[2]!TSImport("PRTime","","Time_NINE","","Date",$CA$11,"Employee",$B$2,"JCJob",$C14,"JCExtra",$D14,"JCCostCode",$E14,"WCCode",$B14,"WCState",$G14,"State",$H14,"PayID",$BG$12,"Units",AI14,"UnionID",$B$3,"UnionLocal",$F14,"UnionClass",$I14,"CertifiedClass",$J14)),0) -> 0 | CG14: =IF(AND(NOT(ISBLANK($C14)),NOT(ISBLANK($E14)),$A14="x"),IF(AJ14=0,0,[2]!TSImport("PRTime","","Time_NINE","","Date",$CG$11,"Employee",$B$2,"JCJob",$C14,"JCExtra",$D14,"JCCostCode",$E14,"WCCode",$B14,"WCState",$G14,"State",$H14,"PayID",$BB$12,"Units",AJ14,"UnionID",$B$3,"UnionLocal",$F14,"UnionClass",$I14,"CertifiedClass",$J14)),0) -> 0 | CH14: =IF(AND(NOT(ISBLANK($C14)),NOT(ISBLANK($E14)),$A14="x"),IF(AK14=0,0,[2]!TSImport("PRTime","","Time_NINE","","Date",$CG$11,"Employee",$B$2,"JCJob",$C14,"JCExtra",$D14,"JCCostCode",$E14,"WCCode",$B14,"WCState",$G14,"State",$H14,"PayID",$BC$12,"Units",AK14,"UnionID",$B$3,"UnionLocal",$F14,"UnionClass",$I14,"CertifiedClass",$J14)),0) -> 0 | CI14: =IF(AND(NOT(ISBLANK($C14)),NOT(ISBLANK($E14)),$A14="x"),IF(AL14=0,0,[2]!TSImport("PRTime","","Time_NINE","","Date",$CG$11,"Employee",$B$2,"JCJob",$C14,"JCExtra",$D14,"JCCostCode",$E14,"WCCode",$B14,"WCState",$G14,"State",$H14,"PayID",$BD$12,"Units",AL14,"UnionID",$B$3,"UnionLocal",$F14,"UnionClass",$I14,"CertifiedClass",$J14)),0) -> 0 | CJ14: =IF(AND(NOT(ISBLANK($C14)),NOT(ISBLANK($E14)),$A14="x"),IF(AM14=0,0,[2]!TSImport("PRTime","","Time_NINE","","Date",$CG$11,"Employee",$B$2,"JCJob",$C14,"JCExtra",$D14,"JCCostCode",$E14,"WCCode",$B14,"WCState",$G14,"State",$H14,"PayID",$BE$12,"Units",AM14,"UnionID",$B$3,"UnionLocal",$F14,"UnionClass",$I14,"CertifiedClass",$J14)),0) -> 0 | CK14: =IF(AND(NOT(ISBLANK($C14)),NOT(ISBLANK($E14)),$A14="x"),IF(AN14=0,0,[2]!TSImport("PRTime","","Time_NINE","","Date",$CG$11,"Employee",$B$2,"JCJob",$C14,"JCExtra",$D14,"JCCostCode",$E14,"WCCode",$B14,"WCState",$G14,"State",$H14,"PayID",$BF$12,"Units",AN14,"UnionID",$B$3,"UnionLocal",$F14,"UnionClass",$I14,"CertifiedClass",$J14)),0) -> 0 | CL14: =IF(AND(NOT(ISBLANK($C14)),NOT(ISBLANK($E14)),$A14="x"),IF(AO14=0,0,[2]!TSImport("PRTime","","Time_NINE","","Date",$CG$11,"Employee",$B$2,"JCJob",$C14,"JCExtra",$D14,"JCCostCode",$E14,"WCCode",$B14,"WCState",$G14,"State",$H14,"PayID",$BG$12,"Units",AO14,"UnionID",$B$3,"UnionLocal",$F14,"UnionClass",$I14,"CertifiedClass",$J14)),0) -> 0 | CM14: =IF(AND(NOT(ISBLANK($C14)),NOT(ISBLANK($E14)),$A14="x"),IF(AP14=0,0,[2]!TSImport("PRTime","","Time_NINE","","Date",$CM$11,"Employee",$B$2,"JCJob",$C14,"JCExtra",$D14,"JCCostCode",$E14,"WCCode",$B14,"WCState",$G14,"State",$H14,"PayID",$BB$12,"Units",AP14,"UnionID",$B$3,"UnionLocal",$F14,"UnionClass",$I14,"CertifiedClass",$J14)),0) -> 0 | CN14: =IF(AND(NOT(ISBLANK($C14)),NOT(ISBLANK($E14)),$A14="x"),IF(AQ14=0,0,[2]!TSImport("PRTime","","Time_NINE","","Date",$CM$11,"Employee",$B$2,"JCJob",$C14,"JCExtra",$D14,"JCCostCode",$E14,"WCCode",$B14,"WCState",$G14,"State",$H14,"PayID",$BC$12,"Units",AQ14,"UnionID",$B$3,"UnionLocal",$F14,"UnionClass",$I14,"CertifiedClass",$J14)),0) -> 0 | CO14: =IF(AND(NOT(ISBLANK($C14)),NOT(ISBLANK($E14)),$A14="x"),IF(AR14=0,0,[2]!TSImport("PRTime","","Time_NINE","","Date",$CM$11,"Employee",$B$2,"JCJob",$C14,"JCExtra",$D14,"JCCostCode",$E14,"WCCode",$B14,"WCState",$G14,"State",$H14,"PayID",$BD$12,"Units",AR14,"UnionID",$B$3,"UnionLocal",$F14,"UnionClass",$I14,"CertifiedClass",$J14)),0) -> 0 | CP14: =IF(AND(NOT(ISBLANK($C14)),NOT(ISBLANK($E14)),$A14="x"),IF(AS14=0,0,[2]!TSImport("PRTime","","Time_NINE","","Date",$CM$11,"Employee",$B$2,"JCJob",$C14,"JCExtra",$D14,"JCCostCode",$E14,"WCCode",$B14,"WCState",$G14,"State",$H14,"PayID",$BE$12,"Units",AS14,"UnionID",$B$3,"UnionLocal",$F14,"UnionClass",$I14,"CertifiedClass",$J14)),0) -> 0 | CQ14: =IF(AND(NOT(ISBLANK($C14)),NOT(ISBLANK($E14)),$A14="x"),IF(AT14=0,0,[2]!TSImport("PRTime","","Time_NINE","","Date",$CM$11,"Employee",$B$2,"JCJob",$C14,"JCExtra",$D14,"JCCostCode",$E14,"WCCode",$B14,"WCState",$G14,"State",$H14,"PayID",$BF$12,"Units",AT14,"UnionID",$B$3,"UnionLocal",$F14,"UnionClass",$I14,"CertifiedClass",$J14)),0) -> 0 | CR14: =IF(AND(NOT(ISBLANK($C14)),NOT(ISBLANK($E14)),$A14="x"),IF(AU14=0,0,[2]!TSImport("PRTime","","Time_NINE","","Date",$CM$11,"Employee",$B$2,"JCJob",$C14,"JCExtra",$D14,"JCCostCode",$E14,"WCCode",$B14,"WCState",$G14,"State",$H14,"PayID",$BG$12,"Units",AU14,"UnionID",$B$3,"UnionLocal",$F14,"UnionClass",$I14,"CertifiedClass",$J14)),0) -> 0 | CS14: =IF(AND(NOT(ISBLANK($C14)),NOT(ISBLANK($E14)),$A14="x"),IF(AV14=0,0,[2]!TSImport("PRTime","","Time_NINE","","Date",$CS$11,"Employee",$B$2,"JCJob",$C14,"JCExtra",$D14,"JCCostCode",$E14,"WCCode",$B14,"WCState",$G14,"State",$H14,"PayID",$BB$12,"Units",AV14,"UnionID",$B$3,"UnionLocal",$F14,"UnionClass",$I14,"CertifiedClass",$J14)),0) -> 0 | CT14: =IF(AND(NOT(ISBLANK($C14)),NOT(ISBLANK($E14)),$A14="x"),IF(AW14=0,0,[2]!TSImport("PRTime","","Time_NINE","","Date",$CS$11,"Employee",$B$2,"JCJob",$C14,"JCExtra",$D14,"JCCostCode",$E14,"WCCode",$B14,"WCState",$G14,"State",$H14,"PayID",$BC$12,"Units",AW14,"UnionID",$B$3,"UnionLocal",$F14,"UnionClass",$I14,"CertifiedClass",$J14)),0) -> 0 | CU14: =IF(AND(NOT(ISBLANK($C14)),NOT(ISBLANK($E14)),$A14="x"),IF(AX14=0,0,[2]!TSImport("PRTime","","Time_NINE","","Date",$CS$11,"Employee",$B$2,"JCJob",$C14,"JCExtra",$D14,"JCCostCode",$E14,"WCCode",$B14,"WCState",$G14,"State",$H14,"PayID",$BD$12,"Units",AX14,"UnionID",$B$3,"UnionLocal",$F14,"UnionClass",$I14,"CertifiedClass",$J14)),0) -> 0 | CV14: =IF(AND(NOT(ISBLANK($C14)),NOT(ISBLANK($E14)),$A14="x"),IF(AY14=0,0,[2]!TSImport("PRTime","","Time_NINE","","Date",$CS$11,"Employee",$B$2,"JCJob",$C14,"JCExtra",$D14,"JCCostCode",$E14,"WCCode",$B14,"WCState",$G14,"State",$H14,"PayID",$BE$12,"Units",AY14,"UnionID",$B$3,"UnionLocal",$F14,"UnionClass",$I14,"CertifiedClass",$J14)),0) -> 0 | CW14: =IF(AND(NOT(ISBLANK($C14)),NOT(ISBLANK($E14)),$A14="x"),IF(AZ14=0,0,[2]!TSImport("PRTime","","Time_NINE","","Date",$CS$11,"Employee",$B$2,"JCJob",$C14,"JCExtra",$D14,"JCCostCode",$E14,"WCCode",$B14,"WCState",$G14,"State",$H14,"PayID",$BF$12,"Units",AZ14,"UnionID",$B$3,"UnionLocal",$F14,"UnionClass",$I14,"CertifiedClass",$J14)),0) -> 0 | CX14: =IF(AND(NOT(ISBLANK($C14)),NOT(ISBLANK($E14)),$A14="x"),IF(BA14=0,0,[2]!TSImport("PRTime","","Time_NINE","","Date",$CS$11,"Employee",$B$2,"JCJob",$C14,"JCExtra",$D14,"JCCostCode",$E14,"WCCode",$B14,"WCState",$G14,"State",$H14,"PayID",$BG$12,"Units",BA14,"UnionID",$B$3,"UnionLocal",$F14,"UnionClass",$I14,"CertifiedClass",$J14)),0) -> 0
A15: =IF(ISBLANK(C15),"",IF(ISBLANK($D$3),"",$D$3)) | F15: =IF(ISBLANK($B$4),"",$B$4) | J15: =IF($K15=0,"",IF($K15<10,"0"&$K15,$K15)) | BB15: =SUM(AV15,AP15,AJ15,AD15,X15,R15,L15) -> 0 | BC15: =SUM(AW15,AQ15,AK15,AE15,Y15,S15,M15) -> 0 | BD15: =SUM(AX15,AR15,AL15,AF15,Z15,T15,N15) -> 0 | BE15: =SUM(AY15,AS15,AM15,AG15,AA15,U15,O15) -> 0 | BF15: =SUM(AZ15,AT15,AN15,AH15,AB15,V15,P15) -> 0 | BG15: =SUM(BA15,AU15,AO15,AI15,AC15,W15,Q15) -> 0 | BH15: =SUM(TimeSheet34[[#This Row],[1]:[4A]]) -> 0 | BI15: =IF(AND(NOT(ISBLANK($C15)),NOT(ISBLANK($E15)),$A15="x"),IF(L15=0,0,[2]!TSImport("PRTime","","Time_NINE","","Date",$BI$11,"Employee",$B$2,"JCJob",$C15,"JCExtra",$D15,"JCCostCode",$E15,"WCCode",$B15,"WCState",$G15,"State",$H15,"PayID",$BB$12,"Units",L15,"UnionID",$B$3,"UnionLocal",$F15,"UnionClass",$I15,"CertifiedClass",$J15)),0) -> 0 | BJ15: =IF(AND(NOT(ISBLANK($C15)),NOT(ISBLANK($E15)),$A15="x"),IF(M15=0,0,[2]!TSImport("PRTime","","Time_NINE","","Date",$BI$11,"Employee",$B$2,"JCJob",$C15,"JCExtra",$D15,"JCCostCode",$E15,"WCCode",$B15,"WCState",$G15,"State",$H15,"PayID",$BC$12,"Units",M15,"UnionID",$B$3,"UnionLocal",$F15,"UnionClass",$I15,"CertifiedClass",$J15)),0) -> 0 | BK15: =IF(AND(NOT(ISBLANK($C15)),NOT(ISBLANK($E15)),$A15="x"),IF(N15=0,0,[2]!TSImport("PRTime","","Time_NINE","","Date",$BI$11,"Employee",$B$2,"JCJob",$C15,"JCExtra",$D15,"JCCostCode",$E15,"WCCode",$B15,"WCState",$G15,"State",$H15,"PayID",$BD$12,"Units",N15,"UnionID",$B$3,"UnionLocal",$F15,"UnionClass",$I15,"CertifiedClass",$J15)),0) -> 0 | BL15: =IF(AND(NOT(ISBLANK($C15)),NOT(ISBLANK($E15)),$A15="x"),IF(O15=0,0,[2]!TSImport("PRTime","","Time_NINE","","Date",$BI$11,"Employee",$B$2,"JCJob",$C15,"JCExtra",$D15,"JCCostCode",$E15,"WCCode",$B15,"WCState",$G15,"State",$H15,"PayID",$BE$12,"Units",O15,"UnionID",$B$3,"UnionLocal",$F15,"UnionClass",$I15,"CertifiedClass",$J15)),0) -> 0 | BM15: =IF(AND(NOT(ISBLANK($C15)),NOT(ISBLANK($E15)),$A15="x"),IF(P15=0,0,[2]!TSImport("PRTime","","Time_NINE","","Date",$BI$11,"Employee",$B$2,"JCJob",$C15,"JCExtra",$D15,"JCCostCode",$E15,"WCCode",$B15,"WCState",$G15,"State",$H15,"PayID",$BF$12,"Units",P15,"UnionID",$B$3,"UnionLocal",$F15,"UnionClass",$I15,"CertifiedClass",$J15)),0) -> 0 | BN15: =IF(AND(NOT(ISBLANK($C15)),NOT(ISBLANK($E15)),$A15="x"),IF(Q15=0,0,[2]!TSImport("PRTime","","Time_NINE","","Date",$BI$11,"Employee",$B$2,"JCJob",$C15,"JCExtra",$D15,"JCCostCode",$E15,"WCCode",$B15,"WCState",$G15,"State",$H15,"PayID",$BG$12,"Units",Q15,"UnionID",$B$3,"UnionLocal",$F15,"UnionClass",$I15,"CertifiedClass",$J15)),0) -> 0 | BO15: =IF(AND(NOT(ISBLANK($C15)),NOT(ISBLANK($E15)),$A15="x"),IF(R15=0,0,[2]!TSImport("PRTime","","Time_NINE","","Date",$BO$11,"Employee",$B$2,"JCJob",$C15,"JCExtra",$D15,"JCCostCode",$E15,"WCCode",$B15,"WCState",$G15,"State",$H15,"PayID",$BB$12,"Units",R15,"UnionID",$B$3,"UnionLocal",$F15,"UnionClass",$I15,"CertifiedClass",$J15)),0) -> 0 | BP15: =IF(AND(NOT(ISBLANK($C15)),NOT(ISBLANK($E15)),$A15="x"),IF(S15=0,0,[2]!TSImport("PRTime","","Time_NINE","","Date",$BO$11,"Employee",$B$2,"JCJob",$C15,"JCExtra",$D15,"JCCostCode",$E15,"WCCode",$B15,"WCState",$G15,"State",$H15,"PayID",$BC$12,"Units",S15,"UnionID",$B$3,"UnionLocal",$F15,"UnionClass",$I15,"CertifiedClass",$J15)),0) -> 0 | BQ15: =IF(AND(NOT(ISBLANK($C15)),NOT(ISBLANK($E15)),$A15="x"),IF(T15=0,0,[2]!TSImport("PRTime","","Time_NINE","","Date",$BO$11,"Employee",$B$2,"JCJob",$C15,"JCExtra",$D15,"JCCostCode",$E15,"WCCode",$B15,"WCState",$G15,"State",$H15,"PayID",$BD$12,"Units",T15,"UnionID",$B$3,"UnionLocal",$F15,"UnionClass",$I15,"CertifiedClass",$J15)),0) -> 0 | BR15: =IF(AND(NOT(ISBLANK($C15)),NOT(ISBLANK($E15)),$A15="x"),IF(U15=0,0,[2]!TSImport("PRTime","","Time_NINE","","Date",$BO$11,"Employee",$B$2,"JCJob",$C15,"JCExtra",$D15,"JCCostCode",$E15,"WCCode",$B15,"WCState",$G15,"State",$H15,"PayID",$BE$12,"Units",U15,"UnionID",$B$3,"UnionLocal",$F15,"UnionClass",$I15,"CertifiedClass",$J15)),0) -> 0 | BS15: =IF(AND(NOT(ISBLANK($C15)),NOT(ISBLANK($E15)),$A15="x"),IF(V15=0,0,[2]!TSImport("PRTime","","Time_NINE","","Date",$BO$11,"Employee",$B$2,"JCJob",$C15,"JCExtra",$D15,"JCCostCode",$E15,"WCCode",$B15,"WCState",$G15,"State",$H15,"PayID",$BF$12,"Units",V15,"UnionID",$B$3,"UnionLocal",$F15,"UnionClass",$I15,"CertifiedClass",$J15)),0) -> 0 | BT15: =IF(AND(NOT(ISBLANK($C15)),NOT(ISBLANK($E15)),$A15="x"),IF(W15=0,0,[2]!TSImport("PRTime","","Time_NINE","","Date",$BO$11,"Employee",$B$2,"JCJob",$C15,"JCExtra",$D15,"JCCostCode",$E15,"WCCode",$B15,"WCState",$G15,"State",$H15,"PayID",$BG$12,"Units",W15,"UnionID",$B$3,"UnionLocal",$F15,"UnionClass",$I15,"CertifiedClass",$J15)),0) -> 0 | BU15: =IF(AND(NOT(ISBLANK($C15)),NOT(ISBLANK($E15)),$A15="x"),IF(X15=0,0,[2]!TSImport("PRTime","","Time_NINE","","Date",$BU$11,"Employee",$B$2,"JCJob",$C15,"JCExtra",$D15,"JCCostCode",$E15,"WCCode",$B15,"WCState",$G15,"State",$H15,"PayID",$BB$12,"Units",X15,"UnionID",$B$3,"UnionLocal",$F15,"UnionClass",$I15,"CertifiedClass",$J15)),0) -> 0 | BV15: =IF(AND(NOT(ISBLANK($C15)),NOT(ISBLANK($E15)),$A15="x"),IF(Y15=0,0,[2]!TSImport("PRTime","","Time_NINE","","Date",$BU$11,"Employee",$B$2,"JCJob",$C15,"JCExtra",$D15,"JCCostCode",$E15,"WCCode",$B15,"WCState",$G15,"State",$H15,"PayID",$BC$12,"Units",Y15,"UnionID",$B$3,"UnionLocal",$F15,"UnionClass",$I15,"CertifiedClass",$J15)),0) -> 0 | BW15: =IF(AND(NOT(ISBLANK($C15)),NOT(ISBLANK($E15)),$A15="x"),IF(Z15=0,0,[2]!TSImport("PRTime","","Time_NINE","","Date",$BU$11,"Employee",$B$2,"JCJob",$C15,"JCExtra",$D15,"JCCostCode",$E15,"WCCode",$B15,"WCState",$G15,"State",$H15,"PayID",$BD$12,"Units",Z15,"UnionID",$B$3,"UnionLocal",$F15,"UnionClass",$I15,"CertifiedClass",$J15)),0) -> 0 | BX15: =IF(AND(NOT(ISBLANK($C15)),NOT(ISBLANK($E15)),$A15="x"),IF(AA15=0,0,[2]!TSImport("PRTime","","Time_NINE","","Date",$BU$11,"Employee",$B$2,"JCJob",$C15,"JCExtra",$D15,"JCCostCode",$E15,"WCCode",$B15,"WCState",$G15,"State",$H15,"PayID",$BE$12,"Units",AA15,"UnionID",$B$3,"UnionLocal",$F15,"UnionClass",$I15,"CertifiedClass",$J15)),0) -> 0 | BY15: =IF(AND(NOT(ISBLANK($C15)),NOT(ISBLANK($E15)),$A15="x"),IF(AB15=0,0,[2]!TSImport("PRTime","","Time_NINE","","Date",$BU$11,"Employee",$B$2,"JCJob",$C15,"JCExtra",$D15,"JCCostCode",$E15,"WCCode",$B15,"WCState",$G15,"State",$H15,"PayID",$BF$12,"Units",AB15,"UnionID",$B$3,"UnionLocal",$F15,"UnionClass",$I15,"CertifiedClass",$J15)),0) -> 0 | BZ15: =IF(AND(NOT(ISBLANK($C15)),NOT(ISBLANK($E15)),$A15="x"),IF(AC15=0,0,[2]!TSImport("PRTime","","Time_NINE","","Date",$BU$11,"Employee",$B$2,"JCJob",$C15,"JCExtra",$D15,"JCCostCode",$E15,"WCCode",$B15,"WCState",$G15,"State",$H15,"PayID",$BG$12,"Units",AC15,"UnionID",$B$3,"UnionLocal",$F15,"UnionClass",$I15,"CertifiedClass",$J15)),0) -> 0 | CA15: =IF(AND(NOT(ISBLANK($C15)),NOT(ISBLANK($E15)),$A15="x"),IF(AD15=0,0,[2]!TSImport("PRTime","","Time_NINE","","Date",$CA$11,"Employee",$B$2,"JCJob",$C15,"JCExtra",$D15,"JCCostCode",$E15,"WCCode",$B15,"WCState",$G15,"State",$H15,"PayID",$BB$12,"Units",AD15,"UnionID",$B$3,"UnionLocal",$F15,"UnionClass",$I15,"CertifiedClass",$J15)),0) -> 0 | CB15: =IF(AND(NOT(ISBLANK($C15)),NOT(ISBLANK($E15)),$A15="x"),IF(AE15=0,0,[2]!TSImport("PRTime","","Time_NINE","","Date",$CA$11,"Employee",$B$2,"JCJob",$C15,"JCExtra",$D15,"JCCostCode",$E15,"WCCode",$B15,"WCState",$G15,"State",$H15,"PayID",$BC$12,"Units",AE15,"UnionID",$B$3,"UnionLocal",$F15,"UnionClass",$I15,"CertifiedClass",$J15)),0) -> 0 | CC15: =IF(AND(NOT(ISBLANK($C15)),NOT(ISBLANK($E15)),$A15="x"),IF(AF15=0,0,[2]!TSImport("PRTime","","Time_NINE","","Date",$CA$11,"Employee",$B$2,"JCJob",$C15,"JCExtra",$D15,"JCCostCode",$E15,"WCCode",$B15,"WCState",$G15,"State",$H15,"PayID",$BD$12,"Units",AF15,"UnionID",$B$3,"UnionLocal",$F15,"UnionClass",$I15,"CertifiedClass",$J15)),0) -> 0 | CD15: =IF(AND(NOT(ISBLANK($C15)),NOT(ISBLANK($E15)),$A15="x"),IF(AG15=0,0,[2]!TSImport("PRTime","","Time_NINE","","Date",$CA$11,"Employee",$B$2,"JCJob",$C15,"JCExtra",$D15,"JCCostCode",$E15,"WCCode",$B15,"WCState",$G15,"State",$H15,"PayID",$BE$12,"Units",AG15,"UnionID",$B$3,"UnionLocal",$F15,"UnionClass",$I15,"CertifiedClass",$J15)),0) -> 0 | CE15: =IF(AND(NOT(ISBLANK($C15)),NOT(ISBLANK($E15)),$A15="x"),IF(AH15=0,0,[2]!TSImport("PRTime","","Time_NINE","","Date",$CA$11,"Employee",$B$2,"JCJob",$C15,"JCExtra",$D15,"JCCostCode",$E15,"WCCode",$B15,"WCState",$G15,"State",$H15,"PayID",$BF$12,"Units",AH15,"UnionID",$B$3,"UnionLocal",$F15,"UnionClass",$I15,"CertifiedClass",$J15)),0) -> 0 | CF15: =IF(AND(NOT(ISBLANK($C15)),NOT(ISBLANK($E15)),$A15="x"),IF(AI15=0,0,[2]!TSImport("PRTime","","Time_NINE","","Date",$CA$11,"Employee",$B$2,"JCJob",$C15,"JCExtra",$D15,"JCCostCode",$E15,"WCCode",$B15,"WCState",$G15,"State",$H15,"PayID",$BG$12,"Units",AI15,"UnionID",$B$3,"UnionLocal",$F15,"UnionClass",$I15,"CertifiedClass",$J15)),0) -> 0 | CG15: =IF(AND(NOT(ISBLANK($C15)),NOT(ISBLANK($E15)),$A15="x"),IF(AJ15=0,0,[2]!TSImport("PRTime","","Time_NINE","","Date",$CG$11,"Employee",$B$2,"JCJob",$C15,"JCExtra",$D15,"JCCostCode",$E15,"WCCode",$B15,"WCState",$G15,"State",$H15,"PayID",$BB$12,"Units",AJ15,"UnionID",$B$3,"UnionLocal",$F15,"UnionClass",$I15,"CertifiedClass",$J15)),0) -> 0 | CH15: =IF(AND(NOT(ISBLANK($C15)),NOT(ISBLANK($E15)),$A15="x"),IF(AK15=0,0,[2]!TSImport("PRTime","","Time_NINE","","Date",$CG$11,"Employee",$B$2,"JCJob",$C15,"JCExtra",$D15,"JCCostCode",$E15,"WCCode",$B15,"WCState",$G15,"State",$H15,"PayID",$BC$12,"Units",AK15,"UnionID",$B$3,"UnionLocal",$F15,"UnionClass",$I15,"CertifiedClass",$J15)),0) -> 0 | CI15: =IF(AND(NOT(ISBLANK($C15)),NOT(ISBLANK($E15)),$A15="x"),IF(AL15=0,0,[2]!TSImport("PRTime","","Time_NINE","","Date",$CG$11,"Employee",$B$2,"JCJob",$C15,"JCExtra",$D15,"JCCostCode",$E15,"WCCode",$B15,"WCState",$G15,"State",$H15,"PayID",$BD$12,"Units",AL15,"UnionID",$B$3,"UnionLocal",$F15,"UnionClass",$I15,"CertifiedClass",$J15)),0) -> 0 | CJ15: =IF(AND(NOT(ISBLANK($C15)),NOT(ISBLANK($E15)),$A15="x"),IF(AM15=0,0,[2]!TSImport("PRTime","","Time_NINE","","Date",$CG$11,"Employee",$B$2,"JCJob",$C15,"JCExtra",$D15,"JCCostCode",$E15,"WCCode",$B15,"WCState",$G15,"State",$H15,"PayID",$BE$12,"Units",AM15,"UnionID",$B$3,"UnionLocal",$F15,"UnionClass",$I15,"CertifiedClass",$J15)),0) -> 0 | CK15: =IF(AND(NOT(ISBLANK($C15)),NOT(ISBLANK($E15)),$A15="x"),IF(AN15=0,0,[2]!TSImport("PRTime","","Time_NINE","","Date",$CG$11,"Employee",$B$2,"JCJob",$C15,"JCExtra",$D15,"JCCostCode",$E15,"WCCode",$B15,"WCState",$G15,"State",$H15,"PayID",$BF$12,"Units",AN15,"UnionID",$B$3,"UnionLocal",$F15,"UnionClass",$I15,"CertifiedClass",$J15)),0) -> 0 | CL15: =IF(AND(NOT(ISBLANK($C15)),NOT(ISBLANK($E15)),$A15="x"),IF(AO15=0,0,[2]!TSImport("PRTime","","Time_NINE","","Date",$CG$11,"Employee",$B$2,"JCJob",$C15,"JCExtra",$D15,"JCCostCode",$E15,"WCCode",$B15,"WCState",$G15,"State",$H15,"PayID",$BG$12,"Units",AO15,"UnionID",$B$3,"UnionLocal",$F15,"UnionClass",$I15,"CertifiedClass",$J15)),0) -> 0 | CM15: =IF(AND(NOT(ISBLANK($C15)),NOT(ISBLANK($E15)),$A15="x"),IF(AP15=0,0,[2]!TSImport("PRTime","","Time_NINE","","Date",$CM$11,"Employee",$B$2,"JCJob",$C15,"JCExtra",$D15,"JCCostCode",$E15,"WCCode",$B15,"WCState",$G15,"State",$H15,"PayID",$BB$12,"Units",AP15,"UnionID",$B$3,"UnionLocal",$F15,"UnionClass",$I15,"CertifiedClass",$J15)),0) -> 0 | CN15: =IF(AND(NOT(ISBLANK($C15)),NOT(ISBLANK($E15)),$A15="x"),IF(AQ15=0,0,[2]!TSImport("PRTime","","Time_NINE","","Date",$CM$11,"Employee",$B$2,"JCJob",$C15,"JCExtra",$D15,"JCCostCode",$E15,"WCCode",$B15,"WCState",$G15,"State",$H15,"PayID",$BC$12,"Units",AQ15,"UnionID",$B$3,"UnionLocal",$F15,"UnionClass",$I15,"CertifiedClass",$J15)),0) -> 0 | CO15: =IF(AND(NOT(ISBLANK($C15)),NOT(ISBLANK($E15)),$A15="x"),IF(AR15=0,0,[2]!TSImport("PRTime","","Time_NINE","","Date",$CM$11,"Employee",$B$2,"JCJob",$C15,"JCExtra",$D15,"JCCostCode",$E15,"WCCode",$B15,"WCState",$G15,"State",$H15,"PayID",$BD$12,"Units",AR15,"UnionID",$B$3,"UnionLocal",$F15,"UnionClass",$I15,"CertifiedClass",$J15)),0) -> 0 | CP15: =IF(AND(NOT(ISBLANK($C15)),NOT(ISBLANK($E15)),$A15="x"),IF(AS15=0,0,[2]!TSImport("PRTime","","Time_NINE","","Date",$CM$11,"Employee",$B$2,"JCJob",$C15,"JCExtra",$D15,"JCCostCode",$E15,"WCCode",$B15,"WCState",$G15,"State",$H15,"PayID",$BE$12,"Units",AS15,"UnionID",$B$3,"UnionLocal",$F15,"UnionClass",$I15,"CertifiedClass",$J15)),0) -> 0 | CQ15: =IF(AND(NOT(ISBLANK($C15)),NOT(ISBLANK($E15)),$A15="x"),IF(AT15=0,0,[2]!TSImport("PRTime","","Time_NINE","","Date",$CM$11,"Employee",$B$2,"JCJob",$C15,"JCExtra",$D15,"JCCostCode",$E15,"WCCode",$B15,"WCState",$G15,"State",$H15,"PayID",$BF$12,"Units",AT15,"UnionID",$B$3,"UnionLocal",$F15,"UnionClass",$I15,"CertifiedClass",$J15)),0) -> 0 | CR15: =IF(AND(NOT(ISBLANK($C15)),NOT(ISBLANK($E15)),$A15="x"),IF(AU15=0,0,[2]!TSImport("PRTime","","Time_NINE","","Date",$CM$11,"Employee",$B$2,"JCJob",$C15,"JCExtra",$D15,"JCCostCode",$E15,"WCCode",$B15,"WCState",$G15,"State",$H15,"PayID",$BG$12,"Units",AU15,"UnionID",$B$3,"UnionLocal",$F15,"UnionClass",$I15,"CertifiedClass",$J15)),0) -> 0 | CS15: =IF(AND(NOT(ISBLANK($C15)),NOT(ISBLANK($E15)),$A15="x"),IF(AV15=0,0,[2]!TSImport("PRTime","","Time_NINE","","Date",$CS$11,"Employee",$B$2,"JCJob",$C15,"JCExtra",$D15,"JCCostCode",$E15,"WCCode",$B15,"WCState",$G15,"State",$H15,"PayID",$BB$12,"Units",AV15,"UnionID",$B$3,"UnionLocal",$F15,"UnionClass",$I15,"CertifiedClass",$J15)),0) -> 0 | CT15: =IF(AND(NOT(ISBLANK($C15)),NOT(ISBLANK($E15)),$A15="x"),IF(AW15=0,0,[2]!TSImport("PRTime","","Time_NINE","","Date",$CS$11,"Employee",$B$2,"JCJob",$C15,"JCExtra",$D15,"JCCostCode",$E15,"WCCode",$B15,"WCState",$G15,"State",$H15,"PayID",$BC$12,"Units",AW15,"UnionID",$B$3,"UnionLocal",$F15,"UnionClass",$I15,"CertifiedClass",$J15)),0) -> 0 | CU15: =IF(AND(NOT(ISBLANK($C15)),NOT(ISBLANK($E15)),$A15="x"),IF(AX15=0,0,[2]!TSImport("PRTime","","Time_NINE","","Date",$CS$11,"Employee",$B$2,"JCJob",$C15,"JCExtra",$D15,"JCCostCode",$E15,"WCCode",$B15,"WCState",$G15,"State",$H15,"PayID",$BD$12,"Units",AX15,"UnionID",$B$3,"UnionLocal",$F15,"UnionClass",$I15,"CertifiedClass",$J15)),0) -> 0 | CV15: =IF(AND(NOT(ISBLANK($C15)),NOT(ISBLANK($E15)),$A15="x"),IF(AY15=0,0,[2]!TSImport("PRTime","","Time_NINE","","Date",$CS$11,"Employee",$B$2,"JCJob",$C15,"JCExtra",$D15,"JCCostCode",$E15,"WCCode",$B15,"WCState",$G15,"State",$H15,"PayID",$BE$12,"Units",AY15,"UnionID",$B$3,"UnionLocal",$F15,"UnionClass",$I15,"CertifiedClass",$J15)),0) -> 0 | CW15: =IF(AND(NOT(ISBLANK($C15)),NOT(ISBLANK($E15)),$A15="x"),IF(AZ15=0,0,[2]!TSImport("PRTime","","Time_NINE","","Date",$CS$11,"Employee",$B$2,"JCJob",$C15,"JCExtra",$D15,"JCCostCode",$E15,"WCCode",$B15,"WCState",$G15,"State",$H15,"PayID",$BF$12,"Units",AZ15,"UnionID",$B$3,"UnionLocal",$F15,"UnionClass",$I15,"CertifiedClass",$J15)),0) -> 0 | CX15: =IF(AND(NOT(ISBLANK($C15)),NOT(ISBLANK($E15)),$A15="x"),IF(BA15=0,0,[2]!TSImport("PRTime","","Time_NINE","","Date",$CS$11,"Employee",$B$2,"JCJob",$C15,"JCExtra",$D15,"JCCostCode",$E15,"WCCode",$B15,"WCState",$G15,"State",$H15,"PayID",$BG$12,"Units",BA15,"UnionID",$B$3,"UnionLocal",$F15,"UnionClass",$I15,"CertifiedClass",$J15)),0) -> 0
